[2025-07-15T22:49:38.149+0000] {taskinstance.py:1956} INFO - Dependencies all met for dep_context=non-requeueable deps ti=<TaskInstance: python_pipeline.read_csv_file manual__2025-07-15T22:49:34.742266+00:00 [queued]>
[2025-07-15T22:49:38.154+0000] {taskinstance.py:1956} INFO - Dependencies all met for dep_context=requeueable deps ti=<TaskInstance: python_pipeline.read_csv_file manual__2025-07-15T22:49:34.742266+00:00 [queued]>
[2025-07-15T22:49:38.155+0000] {taskinstance.py:2170} INFO - Starting attempt 1 of 1
[2025-07-15T22:49:38.163+0000] {taskinstance.py:2191} INFO - Executing <Task(PythonOperator): read_csv_file> on 2025-07-15 22:49:34.742266+00:00
[2025-07-15T22:49:38.167+0000] {standard_task_runner.py:60} INFO - Started process 9433 to run task
[2025-07-15T22:49:38.169+0000] {standard_task_runner.py:87} INFO - Running: ['***', 'tasks', 'run', 'python_pipeline', 'read_csv_file', 'manual__2025-07-15T22:49:34.742266+00:00', '--job-id', '147', '--raw', '--subdir', 'DAGS_FOLDER/executing_python_pipeline.py', '--cfg-path', '/tmp/tmpn7t8rl77']
[2025-07-15T22:49:38.171+0000] {standard_task_runner.py:88} INFO - Job 147: Subtask read_csv_file
[2025-07-15T22:49:38.210+0000] {task_command.py:423} INFO - Running <TaskInstance: python_pipeline.read_csv_file manual__2025-07-15T22:49:34.742266+00:00 [running]> on host 84e5714b039f
[2025-07-15T22:49:38.251+0000] {taskinstance.py:2480} INFO - Exporting env vars: AIRFLOW_CTX_DAG_OWNER='***' AIRFLOW_CTX_DAG_ID='python_pipeline' AIRFLOW_CTX_TASK_ID='read_csv_file' AIRFLOW_CTX_EXECUTION_DATE='2025-07-15T22:49:34.742266+00:00' AIRFLOW_CTX_TRY_NUMBER='1' AIRFLOW_CTX_DAG_RUN_ID='manual__2025-07-15T22:49:34.742266+00:00'
[2025-07-15T22:49:38.252+0000] {taskinstance.py:2698} ERROR - Task failed with exception
Traceback (most recent call last):
  File "/home/airflow/.local/lib/python3.8/site-packages/airflow/models/taskinstance.py", line 433, in _execute_task
    result = execute_callable(context=context, **execute_callable_kwargs)
  File "/home/airflow/.local/lib/python3.8/site-packages/airflow/operators/python.py", line 199, in execute
    return_value = self.execute_callable()
  File "/home/airflow/.local/lib/python3.8/site-packages/airflow/operators/python.py", line 216, in execute_callable
    return self.python_callable(*self.op_args, **self.op_kwargs)
  File "/opt/airflow/dags/executing_python_pipeline.py", line 12, in read_csv_file
    df = pd.read_csv('/opt/airflow/datasets/insurance.csv')
NameError: name 'pd' is not defined
[2025-07-15T22:49:38.257+0000] {taskinstance.py:1138} INFO - Marking task as FAILED. dag_id=python_pipeline, task_id=read_csv_file, execution_date=20250715T224934, start_date=20250715T224938, end_date=20250715T224938
[2025-07-15T22:49:38.267+0000] {standard_task_runner.py:107} ERROR - Failed to execute job 147 for task read_csv_file (name 'pd' is not defined; 9433)
[2025-07-15T22:49:38.305+0000] {local_task_job_runner.py:234} INFO - Task exited with return code 1
[2025-07-15T22:49:38.316+0000] {taskinstance.py:3280} INFO - 0 downstream tasks scheduled from follow-on schedule check
