[2025-07-15T23:13:53.247+0000] {taskinstance.py:1956} INFO - Dependencies all met for dep_context=non-requeueable deps ti=<TaskInstance: python_pipeline.read_csv_file manual__2025-07-15T23:13:50.960910+00:00 [queued]>
[2025-07-15T23:13:53.251+0000] {taskinstance.py:1956} INFO - Dependencies all met for dep_context=requeueable deps ti=<TaskInstance: python_pipeline.read_csv_file manual__2025-07-15T23:13:50.960910+00:00 [queued]>
[2025-07-15T23:13:53.252+0000] {taskinstance.py:2170} INFO - Starting attempt 1 of 1
[2025-07-15T23:13:53.259+0000] {taskinstance.py:2191} INFO - Executing <Task(PythonOperator): read_csv_file> on 2025-07-15 23:13:50.960910+00:00
[2025-07-15T23:13:53.263+0000] {standard_task_runner.py:60} INFO - Started process 221 to run task
[2025-07-15T23:13:53.265+0000] {standard_task_runner.py:87} INFO - Running: ['***', 'tasks', 'run', 'python_pipeline', 'read_csv_file', 'manual__2025-07-15T23:13:50.960910+00:00', '--job-id', '158', '--raw', '--subdir', 'DAGS_FOLDER/executing_python_pipeline.py', '--cfg-path', '/tmp/tmpa_qimo4k']
[2025-07-15T23:13:53.267+0000] {standard_task_runner.py:88} INFO - Job 158: Subtask read_csv_file
[2025-07-15T23:13:53.306+0000] {task_command.py:423} INFO - Running <TaskInstance: python_pipeline.read_csv_file manual__2025-07-15T23:13:50.960910+00:00 [running]> on host 84e5714b039f
[2025-07-15T23:13:53.350+0000] {taskinstance.py:2480} INFO - Exporting env vars: AIRFLOW_CTX_DAG_OWNER='***' AIRFLOW_CTX_DAG_ID='python_pipeline' AIRFLOW_CTX_TASK_ID='read_csv_file' AIRFLOW_CTX_EXECUTION_DATE='2025-07-15T23:13:50.960910+00:00' AIRFLOW_CTX_TRY_NUMBER='1' AIRFLOW_CTX_DAG_RUN_ID='manual__2025-07-15T23:13:50.960910+00:00'
[2025-07-15T23:13:53.352+0000] {taskinstance.py:2698} ERROR - Task failed with exception
Traceback (most recent call last):
  File "/home/airflow/.local/lib/python3.8/site-packages/airflow/models/taskinstance.py", line 433, in _execute_task
    result = execute_callable(context=context, **execute_callable_kwargs)
  File "/home/airflow/.local/lib/python3.8/site-packages/airflow/operators/python.py", line 199, in execute
    return_value = self.execute_callable()
  File "/home/airflow/.local/lib/python3.8/site-packages/airflow/operators/python.py", line 216, in execute_callable
    return self.python_callable(*self.op_args, **self.op_kwargs)
  File "/opt/airflow/dags/executing_python_pipeline.py", line 14, in read_csv_file
    df = pd.read_csv('/opt/airflow/datasets/insurance.csv')
  File "/home/airflow/.local/lib/python3.8/site-packages/pandas/io/parsers/readers.py", line 912, in read_csv
    return _read(filepath_or_buffer, kwds)
  File "/home/airflow/.local/lib/python3.8/site-packages/pandas/io/parsers/readers.py", line 577, in _read
    parser = TextFileReader(filepath_or_buffer, **kwds)
  File "/home/airflow/.local/lib/python3.8/site-packages/pandas/io/parsers/readers.py", line 1407, in __init__
    self._engine = self._make_engine(f, self.engine)
  File "/home/airflow/.local/lib/python3.8/site-packages/pandas/io/parsers/readers.py", line 1661, in _make_engine
    self.handles = get_handle(
  File "/home/airflow/.local/lib/python3.8/site-packages/pandas/io/common.py", line 859, in get_handle
    handle = open(
FileNotFoundError: [Errno 2] No such file or directory: '/opt/airflow/datasets/insurance.csv'
[2025-07-15T23:13:53.358+0000] {taskinstance.py:1138} INFO - Marking task as FAILED. dag_id=python_pipeline, task_id=read_csv_file, execution_date=20250715T231350, start_date=20250715T231353, end_date=20250715T231353
[2025-07-15T23:13:53.365+0000] {standard_task_runner.py:107} ERROR - Failed to execute job 158 for task read_csv_file ([Errno 2] No such file or directory: '/opt/airflow/datasets/insurance.csv'; 221)
[2025-07-15T23:13:53.398+0000] {local_task_job_runner.py:234} INFO - Task exited with return code 1
[2025-07-15T23:13:53.410+0000] {taskinstance.py:3280} INFO - 0 downstream tasks scheduled from follow-on schedule check
