[2025-07-15T00:43:54.559+0000] {taskinstance.py:1956} INFO - Dependencies all met for dep_context=non-requeueable deps ti=<TaskInstance: cross_task_pass_value.increment_by_1 scheduled__2025-07-14T00:00:00+00:00 [queued]>
[2025-07-15T00:43:54.565+0000] {taskinstance.py:1956} INFO - Dependencies all met for dep_context=requeueable deps ti=<TaskInstance: cross_task_pass_value.increment_by_1 scheduled__2025-07-14T00:00:00+00:00 [queued]>
[2025-07-15T00:43:54.566+0000] {taskinstance.py:2170} INFO - Starting attempt 1 of 1
[2025-07-15T00:43:54.574+0000] {taskinstance.py:2191} INFO - Executing <Task(PythonOperator): increment_by_1> on 2025-07-14 00:00:00+00:00
[2025-07-15T00:43:54.578+0000] {standard_task_runner.py:60} INFO - Started process 221 to run task
[2025-07-15T00:43:54.580+0000] {standard_task_runner.py:87} INFO - Running: ['***', 'tasks', 'run', 'cross_task_pass_value', 'increment_by_1', 'scheduled__2025-07-14T00:00:00+00:00', '--job-id', '100', '--raw', '--subdir', 'DAGS_FOLDER/execute_xcom_pass_values.py', '--cfg-path', '/tmp/tmpv3bf1aak']
[2025-07-15T00:43:54.583+0000] {standard_task_runner.py:88} INFO - Job 100: Subtask increment_by_1
[2025-07-15T00:43:54.631+0000] {task_command.py:423} INFO - Running <TaskInstance: cross_task_pass_value.increment_by_1 scheduled__2025-07-14T00:00:00+00:00 [running]> on host 84e5714b039f
[2025-07-15T00:43:54.681+0000] {taskinstance.py:2480} INFO - Exporting env vars: AIRFLOW_CTX_DAG_OWNER='*** ' AIRFLOW_CTX_DAG_ID='cross_task_pass_value' AIRFLOW_CTX_TASK_ID='increment_by_1' AIRFLOW_CTX_EXECUTION_DATE='2025-07-14T00:00:00+00:00' AIRFLOW_CTX_TRY_NUMBER='1' AIRFLOW_CTX_DAG_RUN_ID='scheduled__2025-07-14T00:00:00+00:00'
[2025-07-15T00:43:54.683+0000] {taskinstance.py:2698} ERROR - Task failed with exception
Traceback (most recent call last):
  File "/home/airflow/.local/lib/python3.8/site-packages/airflow/models/taskinstance.py", line 433, in _execute_task
    result = execute_callable(context=context, **execute_callable_kwargs)
  File "/home/airflow/.local/lib/python3.8/site-packages/airflow/operators/python.py", line 199, in execute
    return_value = self.execute_callable()
  File "/home/airflow/.local/lib/python3.8/site-packages/airflow/operators/python.py", line 216, in execute_callable
    return self.python_callable(*self.op_args, **self.op_kwargs)
TypeError: increment_by_1() missing 1 required positional argument: 'value'
[2025-07-15T00:43:54.688+0000] {taskinstance.py:1138} INFO - Marking task as FAILED. dag_id=cross_task_pass_value, task_id=increment_by_1, execution_date=20250714T000000, start_date=20250715T004354, end_date=20250715T004354
[2025-07-15T00:43:54.696+0000] {standard_task_runner.py:107} ERROR - Failed to execute job 100 for task increment_by_1 (increment_by_1() missing 1 required positional argument: 'value'; 221)
[2025-07-15T00:43:54.713+0000] {local_task_job_runner.py:234} INFO - Task exited with return code 1
[2025-07-15T00:43:54.730+0000] {taskinstance.py:3280} INFO - 0 downstream tasks scheduled from follow-on schedule check
